<?xml version="1.0" encoding="UTF-8"?>
<testng-results ignored="0" total="3" passed="1" failed="1" skipped="1">
  <reporter-output>
  </reporter-output>
  <suite started-at="2024-02-26T18:10:51 TRT" name="Default Suite" finished-at="2024-02-26T18:10:51 TRT" duration-ms="94">
    <groups>
    </groups>
    <test started-at="2024-02-26T18:10:51 TRT" name="Deneme" finished-at="2024-02-26T18:10:51 TRT" duration-ms="94">
      <class name="TestNG.day38.MyTest">
        <test-method signature="test1()[pri:1, instance:TestNG.day38.MyTest@5a955565]" started-at="2024-02-26T18:10:51 TRT" name="test1" finished-at="2024-02-26T18:10:51 TRT" duration-ms="12" status="PASS">
          <reporter-output>
          </reporter-output>
        </test-method> <!-- test1 -->
        <test-method signature="test2()[pri:2, instance:TestNG.day38.MyTest@5a955565]" started-at="2024-02-26T18:10:51 TRT" name="test2" finished-at="2024-02-26T18:10:51 TRT" duration-ms="11" status="FAIL">
          <exception class="java.lang.AssertionError">
            <message>
              <![CDATA[expected [B] but found [A]]]>
            </message>
            <full-stacktrace>
              <![CDATA[java.lang.AssertionError: expected [B] but found [A]
at org.testng.Assert.fail(Assert.java:111)
at org.testng.Assert.failNotEquals(Assert.java:1578)
at org.testng.Assert.assertEqualsImpl(Assert.java:150)
at org.testng.Assert.assertEquals(Assert.java:132)
at org.testng.Assert.assertEquals(Assert.java:656)
at org.testng.Assert.assertEquals(Assert.java:666)
at TestNG.day38.MyTest.test2(MyTest.java:17)
at java.base/jdk.internal.reflect.NativeMethodAccessorImpl.invoke0(Native Method)
at java.base/jdk.internal.reflect.NativeMethodAccessorImpl.invoke(NativeMethodAccessorImpl.java:77)
at java.base/jdk.internal.reflect.DelegatingMethodAccessorImpl.invoke(DelegatingMethodAccessorImpl.java:43)
at java.base/java.lang.reflect.Method.invoke(Method.java:568)
at org.testng.internal.invokers.MethodInvocationHelper.invokeMethod(MethodInvocationHelper.java:139)
at org.testng.internal.invokers.TestInvoker.invokeMethod(TestInvoker.java:664)
at org.testng.internal.invokers.TestInvoker.invokeTestMethod(TestInvoker.java:228)
at org.testng.internal.invokers.MethodRunner.runInSequence(MethodRunner.java:63)
at org.testng.internal.invokers.TestInvoker$MethodInvocationAgent.invoke(TestInvoker.java:961)
at org.testng.internal.invokers.TestInvoker.invokeTestMethods(TestInvoker.java:201)
at org.testng.internal.invokers.TestMethodWorker.invokeTestMethods(TestMethodWorker.java:148)
at org.testng.internal.invokers.TestMethodWorker.run(TestMethodWorker.java:128)
at java.base/java.util.ArrayList.forEach(ArrayList.java:1511)
at org.testng.TestRunner.privateRun(TestRunner.java:819)
at org.testng.TestRunner.run(TestRunner.java:619)
at org.testng.SuiteRunner.runTest(SuiteRunner.java:443)
at org.testng.SuiteRunner.runSequentially(SuiteRunner.java:437)
at org.testng.SuiteRunner.privateRun(SuiteRunner.java:397)
at org.testng.SuiteRunner.run(SuiteRunner.java:336)
at org.testng.SuiteRunnerWorker.runSuite(SuiteRunnerWorker.java:52)
at org.testng.SuiteRunnerWorker.run(SuiteRunnerWorker.java:95)
at org.testng.TestNG.runSuitesSequentially(TestNG.java:1301)
at org.testng.TestNG.runSuitesLocally(TestNG.java:1228)
at org.testng.TestNG.runSuites(TestNG.java:1134)
at org.testng.TestNG.run(TestNG.java:1101)
at com.intellij.rt.testng.IDEARemoteTestNG.run(IDEARemoteTestNG.java:65)
at com.intellij.rt.testng.RemoteTestNGStarter.main(RemoteTestNGStarter.java:105)
]]>
            </full-stacktrace>
          </exception> <!-- java.lang.AssertionError -->
          <reporter-output>
          </reporter-output>
        </test-method> <!-- test2 -->
        <test-method signature="test3()[pri:3, instance:TestNG.day38.MyTest@5a955565]" started-at="2024-02-26T18:10:51 TRT" name="test3" finished-at="2024-02-26T18:10:51 TRT" depends-on-methods="TestNG.day38.MyTest.test2" duration-ms="0" status="SKIP">
          <exception class="java.lang.Throwable">
            <message>
              <![CDATA[Method TestNG.day38.MyTest.test3() on instance TestNG.day38.MyTest@5a955565 depends on not successfully finished methods 
[TestNG.day38.MyTest.test2() on instance TestNG.day38.MyTest@5a955565]]]>
            </message>
            <full-stacktrace>
              <![CDATA[java.lang.Throwable: Method TestNG.day38.MyTest.test3() on instance TestNG.day38.MyTest@5a955565 depends on not successfully finished methods 
[TestNG.day38.MyTest.test2() on instance TestNG.day38.MyTest@5a955565]
at org.testng.internal.invokers.TestInvoker.invokeTestMethods(TestInvoker.java:157)
at org.testng.internal.invokers.TestMethodWorker.invokeTestMethods(TestMethodWorker.java:148)
at org.testng.internal.invokers.TestMethodWorker.run(TestMethodWorker.java:128)
at java.base/java.util.ArrayList.forEach(ArrayList.java:1511)
at org.testng.TestRunner.privateRun(TestRunner.java:819)
at org.testng.TestRunner.run(TestRunner.java:619)
at org.testng.SuiteRunner.runTest(SuiteRunner.java:443)
at org.testng.SuiteRunner.runSequentially(SuiteRunner.java:437)
at org.testng.SuiteRunner.privateRun(SuiteRunner.java:397)
at org.testng.SuiteRunner.run(SuiteRunner.java:336)
at org.testng.SuiteRunnerWorker.runSuite(SuiteRunnerWorker.java:52)
at org.testng.SuiteRunnerWorker.run(SuiteRunnerWorker.java:95)
at org.testng.TestNG.runSuitesSequentially(TestNG.java:1301)
at org.testng.TestNG.runSuitesLocally(TestNG.java:1228)
at org.testng.TestNG.runSuites(TestNG.java:1134)
at org.testng.TestNG.run(TestNG.java:1101)
at com.intellij.rt.testng.IDEARemoteTestNG.run(IDEARemoteTestNG.java:65)
at com.intellij.rt.testng.RemoteTestNGStarter.main(RemoteTestNGStarter.java:105)
]]>
            </full-stacktrace>
          </exception> <!-- java.lang.Throwable -->
          <reporter-output>
          </reporter-output>
        </test-method> <!-- test3 -->
      </class> <!-- TestNG.day38.MyTest -->
    </test> <!-- Deneme -->
  </suite> <!-- Default Suite -->
</testng-results>
